/geode2/home/u050/kmluong/BigRed200/Deep-learning-intensity-downscaling/preprocess/MERRA2tc_domain.py:296: DtypeWarning: Columns (1,8,9) have mixed types. Specify dtype option on import or set low_memory=False.
  df=pd.read_csv(csvdataset, usecols=selected_columns, keep_default_na=False); #read data using pandas read csv
Total: 29383
Traceback (most recent call last):
  File "/N/u/kmluong/BigRed200/.local/lib/python3.10/site-packages/xarray/backends/file_manager.py", line 211, in _acquire_with_cache_info
    file = self._cache[self._key]
  File "/N/u/kmluong/BigRed200/.local/lib/python3.10/site-packages/xarray/backends/lru_cache.py", line 56, in __getitem__
    value = self._cache[key]
KeyError: [<class 'netCDF4._netCDF4.Dataset'>, ('/N/u/tqluu/BigRed200/@PUBLIC/nasa-merra2-full/MERRA2_300.inst3_3d_asm_Np.20010527.nc4',), 'r', (('clobber', True), ('diskless', False), ('format', 'NETCDF4'), ('persist', False)), '4e58fcd4-5813-4a3a-8958-04de431fed73']

During handling of the above exception, another exception occurred:

Traceback (most recent call last):
  File "/geode2/home/u050/kmluong/BigRed200/Deep-learning-intensity-downscaling/preprocess/MERRA2tc_domain.py", line 426, in <module>
    merge_data(csvdataset, regions=['EP', 'NA', 'WP'],windowsize=[25,25], datapath=datapath)
  File "/geode2/home/u050/kmluong/BigRed200/Deep-learning-intensity-downscaling/preprocess/MERRA2tc_domain.py", line 375, in merge_data
    dataset = xr.open_dataset(dataname)
  File "/N/u/kmluong/BigRed200/.local/lib/python3.10/site-packages/xarray/backends/api.py", line 572, in open_dataset
    backend_ds = backend.open_dataset(
  File "/N/u/kmluong/BigRed200/.local/lib/python3.10/site-packages/xarray/backends/netCDF4_.py", line 644, in open_dataset
    store = NetCDF4DataStore.open(
  File "/N/u/kmluong/BigRed200/.local/lib/python3.10/site-packages/xarray/backends/netCDF4_.py", line 407, in open
    return cls(manager, group=group, mode=mode, lock=lock, autoclose=autoclose)
  File "/N/u/kmluong/BigRed200/.local/lib/python3.10/site-packages/xarray/backends/netCDF4_.py", line 354, in __init__
    self.format = self.ds.data_model
  File "/N/u/kmluong/BigRed200/.local/lib/python3.10/site-packages/xarray/backends/netCDF4_.py", line 416, in ds
    return self._acquire()
  File "/N/u/kmluong/BigRed200/.local/lib/python3.10/site-packages/xarray/backends/netCDF4_.py", line 410, in _acquire
    with self._manager.acquire_context(needs_lock) as root:
  File "/N/soft/sles15/deeplearning/Python-3.10.10/Lib/contextlib.py", line 135, in __enter__
    return next(self.gen)
  File "/N/u/kmluong/BigRed200/.local/lib/python3.10/site-packages/xarray/backends/file_manager.py", line 199, in acquire_context
    file, cached = self._acquire_with_cache_info(needs_lock)
  File "/N/u/kmluong/BigRed200/.local/lib/python3.10/site-packages/xarray/backends/file_manager.py", line 217, in _acquire_with_cache_info
    file = self._opener(*self._args, **kwargs)
  File "src/netCDF4/_netCDF4.pyx", line 2469, in netCDF4._netCDF4.Dataset.__init__
  File "src/netCDF4/_netCDF4.pyx", line 2028, in netCDF4._netCDF4._ensure_nc_success
FileNotFoundError: [Errno 2] No such file or directory: '/N/u/tqluu/BigRed200/@PUBLIC/nasa-merra2-full/MERRA2_300.inst3_3d_asm_Np.20010527.nc4'
